Workbook

Sheet INSTRUCCIONES
B2: MATRIZ DE CAPTURA — SEGUIMIENTO TRIMESTRAL
B3: ProColombia — Subdirección de Planeación
B5: ¿Qué es esta matriz? | C5: Es el formato oficial para reportar los avances trimestrales de su Hoja de Ruta. Reemplaza el diligenciamiento directo en la presentación PowerPoint. Al completarla, la presentación se genera automáticamente.
B8: ¿Qué hojas debo llenar? | C8: 1) CONFIGURACIÓN → Verifique los datos de su área. 2) DOFA → Revise cada ítem y seleccione si Se mantiene, Se elimina o Se actualiza. 3) TENDENCIAS → Revise cada tendencia y actualice si corresponde. 4) LÍNEA ESTRATÉGICA 1, 2, 3 → Escriba los avances del Q en cada acción e indicador. 5) CASOS DE ÉXITO → Registre los casos destacados del trimestre. 6) METAS GENERALES → Ingrese el avance acumulado de cada meta.
B11: Código de colores | C11: 🔵 Azul claro = Campo que usted debe diligenciar. 🟡 Amarillo claro = Información base de la Hoja de Ruta (no editar). ⬜ Gris = Campo automático o protegido (no editar). 🔴 Rojo claro = Campo obligatorio vacío (¡pendiente!).
B14: Reglas importantes | C14: • Los campos de avance tienen un límite de 500 caracteres. Sea conciso y estratégico. • Los estados se seleccionan de listas desplegables, no escriba texto libre. • No modifique la estructura de las hojas (filas, columnas, encabezados). • La hoja MONITOREO le muestra el porcentaje de completitud en tiempo real. • Si necesita más espacio, use la columna de Observaciones.
B17: ¿Cuándo entregar? | C17: Consulte las fechas en la hoja CONFIGURACIÓN. El incumplimiento afecta el consolidado trimestral que se presenta a Presidencia.
B20: Soporte | C20: Para dudas sobre esta matriz: Subdirección de Planeación. Para problemas técnicos con el archivo: Gerencia de Inteligencia Comercial.

Sheet CONFIGURACIÓN
A1: CONFIGURACIÓN GENERAL
A3: Trimestre en seguimiento | B3: Q4
A4: Año | B4: 2025
A5: Tipo de unidad | B5: EJE
A6: Nombre de la unidad | B6: VP Exportaciones
A7: Fecha de envío lineamientos | B7: 2026-01-15
A8: Fecha límite diligenciamiento | B8: 2026-02-15

Sheet DOFA
A1: SEGUIMIENTO DOFA
A2: La columna B contiene la información original de la Hoja de Ruta. En C seleccione el estado. Si actualiza, escriba en D.
A4: Cuadrante | B4: Información Hoja de Ruta (Base) | C4: Estado Seguimiento | D4: Actualización / Cambio
A5: DEBILIDADES
A6: DEB-1 | B6: Planeación estratégica a corto plazo. | C6: Se mantiene
A7: DEB-2 | B7: Desconexión entre indicadores corporativos y actividades operativas. | C7: Se mantiene
A8: DEB-3 | B8: Dificultades para medir el impacto de los servicios empresariales. | C8: Se actualiza | D8: Se avanzó en la implementación de nuevas métricas de impacto con apoyo de GIC.
A9: DEB-4 | B9: Desarticulación entre iniciativas de las diferentes áreas y ejes estratégicos. | C9: Se mantiene
A10: DEB-5 | B10: Disparidades en el conocimiento del equipo sobre procesos técnicos. | C10: Se mantiene
A11: DEB-6 | B11: Incertidumbre en los procesos de selección y promoción interna. | C11: Se elimina
A12: DEB-7 | B12: Vacantes prolongadas (Brasil, Ecuador, Bogotá, Argentina). | C12: Se actualiza | D12: Se cubrieron vacantes en Brasil y Argentina; persisten en Ecuador.
A13: DEB-8 | B13: Falta de un sistema robusto de inducción y capacitación. | C13: Se mantiene
A14: DEB-9 | B14: Oportunidades de mejora en la atención al usuario. | C14: Se mantiene
A15: DEB-10 | B15: Desarrollo insuficiente de tecnologías y plataformas digitales. | C15: Se actualiza | D15: Plataforma Matchmaking en fase piloto con +700 empresas registradas.
A16: OPORTUNIDADES
A17: OPO-1 | B17: Mejora en la articulación con aliados nacionales e internacionales. | C17: Se mantiene
A18: OPO-2 | B18: Aumento de la presencia comercial de Colombia en escenarios globales. | C18: Se mantiene
A19: OPO-3 | B19: Aumentar la confianza del tejido empresarial colombiano en ProColombia. | C19: Se mantiene
A20: OPO-4 | B20: Presencia sólida en mercados internacionales y regiones estratégicas. | C20: Se mantiene
A21: OPO-5 | B21: Sinergia con el área de inversión para atraer oportunidades. | C21: Se actualiza | D21: Se fortaleció la sinergia con VP Inversión en la MCR Bioexpo 2025 Pasto.
A22: OPO-6 | B22: Posibilidad de monetizar los servicios ofrecidos. | C22: Se mantiene
A23: OPO-7 | B23: Posicionamiento internacional de la marca país. | C23: Se mantiene
A24: OPO-8
A25: OPO-9
A26: OPO-10
A27: FORTALEZAS
A28: FOR-1 | B28: Reconocimiento institucional en el sector empresarial y gremial. | C28: Se mantiene
A29: FOR-2 | B29: Extensas bases de datos e información de mercado. | C29: Se mantiene
A30: FOR-3 | B30: Atención personalizada y adaptada a las necesidades de cada empresario. | C30: Se mantiene
A31: FOR-4 | B31: Equipo comprometido y experimentado. | C31: Se mantiene
A32: FOR-5 | B32: Apoyo técnico y comercial de la Gerencia de Inteligencia Comercial. | C32: Se mantiene
A33: FOR-6 | B33: Colaboración sólida con entidades de cooperación internacional. | C33: Se mantiene
A34: FOR-7 | B34: Sistema de Gestión de Calidad robusto. | C34: Se mantiene
A35: FOR-8 | B35: Formación y capacitación continua para el sector exportador. | C35: Se mantiene
A36: FOR-9
A37: FOR-10
A38: AMENAZAS
A39: AME-1 | B39: Aplazamiento de asignación de recursos financieros. | C39: Se mantiene
A40: AME-2 | B40: Impacto de las políticas gubernamentales en la actividad empresarial. | C40: Se mantiene
A41: AME-3 | B41: Incertidumbre sobre la continuidad de lineamientos del Gobierno. | C41: Se mantiene
...

Sheet TENDENCIAS
A1: SEGUIMIENTO TENDENCIAS GENERALES
A2: Describa las tendencias del entorno relevantes para esta unidad en el trimestre.
A4: # | B4: Tendencia Hoja de Ruta (Base) | C4: Estado | D4: Actualización
A5: 1 | B5: Diferencias geopolíticas provocan fragmentación en la IED global. | C5: Se mantiene
A6: 2 | B6: Inversión transfronteriza en servicios en aumento; manufacturas rezagadas. | C6: Se mantiene
A7: 3 | B7: IED en energía eólica y solar como sector de más rápido crecimiento. | C7: Se mantiene
A8: 4 | B8: Nearshoring como oportunidad clave para Colombia en las Américas. | C8: Se actualiza | D8: Tendencia confirmada con crecimiento de exportaciones a EE.UU. y LATAM.
A9: 5 | B9: Crecimiento de exportaciones hacia Asia (+64%), África (+238%), Europa (+9%). | C9: Se actualiza | D9: Datos consolidados al cierre Q4 2025.
A10: 6
A11: 7

Sheet LÍNEA ESTRATÉGICA 1
A1: LÍNEA ESTRATÉGICA 1
A2: Nombre de la línea: | B2: Promover la canasta exportable de bienes y servicios No Minero Energéticos enfocados en el valor agregado y la sostenibilidad.
A4: ACCIONES Y ACTIVIDADES
A5: # | B5: Acción (Hoja de Ruta) | C5: Actividades Clave (Hoja de Ruta) | D5: Avance del Q (texto) | E5: Estado
A6: 1 | B6: Apoyo a empresarios en actividades de promoción | C6: Ferias, ruedas, macrorruedas, showrooms | D6: Se apoyó a empresarios en ferias internacionales, ruedas de negocios con resultados concretos en ventas. | E6: En progreso
A7: 2 | B7: Organización de actividades comerciales masivas y especializadas | C7: MCR, showrooms multicadena | D7: Macrorrueda Bioexpo 2025 Pasto: 84 exportadores, 34 compradores. Ventas+expectativas USD 6,4M. | E7: Completada
A8: 3 | B8: Actividades de promoción con embajadas | C8: Coordinación con misiones diplomáticas | D8: ANUGA 2025 con Embajada en Alemania. Showroom construcción en Aruba con Cónsul. | E8: En progreso
A9: 4 | B9: Impulsar agroindustria y soberanía alimentaria | C9: Ferias agroalimentarias | D9: Fruit Attraction, IFPA, Anuga 2025. Rueda de Cacao y Chocolate con 8 compradores. | E9: En progreso
A10: 5 | B10: Promover exportaciones con prácticas sostenibles | C10: Posicionar oferta sostenible | D10: DYNAMO: USD 6M con Amazon España. Estrategia GREENAMO. Empresas VERDI, FIBRA CARPETS. | E10: En progreso
A11: 6 | B11: Búsqueda y seguimiento de oportunidades de negocio | C11: +350 exportadores apoyados | D11: Industrias 4.0: +350 exportadores. Sistema Moda: 936 empresas con 70 países. | E11: En progreso
A12: 7 | B12: Desarrollo de plataformas digitales | C12: Plataforma Matchmaking | D12: Matchmaking en fase piloto con +700 empresas exportadoras registradas. | E12: En progreso
A13: 8 | B13: Priorizar sectores y mercados internacionales | C13: Focalización estratégica | D13: Industrias 4.0, Químicos y Ciencias de la Vida, Metalmecánica en Europa, Norteamérica, LATAM. | E13: En progreso
A14: 9
A15: 10
A16: 11
A17: 12
A18: 13
A19: 14
A20: 15
A21: 16
A22: 17
A23: 18
A24: 19
A25: 20
A26: 21
A28: INDICADORES DE ÉXITO / RESULTADOS
A29: # | B29: Indicador | C29: Meta 2026 | D29: Avance Acumulado Q | E29: Observaciones
A30: 1 | B30: Nuevas oportunidades de exportaciones etapas 1 y 4 | C30: 16435 | D30: 20361 | E30: Superado
A31: 2 | B31: Nuevas empresas con oportunidades (1-4) | C31: 530 | D31: 1043 | E31: Superado
A32: 3 | B32: Monto de negocios (USD) | C32: 4286480 | D32: 3195958727 | E32: Superado
A33: 4 | B33: Compradores con negocios | C33: 5550 | D33: 6346 | E33: Superado
A34: 5 | B34: Compradores nuevos con negocios | C34: 2293 | D34: 3156 | E34: Superado
A35: 6 | B35: Empresas exterior con servicios de exportación | C35: 6318 | D35: 5961 | E35: En progreso
A36: 7 | B36: Empresas con negocios | C36: 3330 | D36: 3392 | E36: Superado
A37: 8 | B37: Empresas con negocios (Mipymes) | C37: 2000 | D37: 2753 | E37: Superado
A38: 9
A39: 10

Sheet LÍNEA ESTRATÉGICA 2
A1: LÍNEA ESTRATÉGICA 2
A2: Nombre de la línea: | B2: Apoyar la diversificación de exportaciones No Minero Energéticas con enfoque en territorios priorizados.
A4: ACCIONES Y ACTIVIDADES
A5: # | B5: Acción (Hoja de Ruta) | C5: Actividades Clave (Hoja de Ruta) | D5: Avance del Q (texto) | E5: Estado
A6: 1 | B6: Impulsar MiPymes de los territorios | C6: Identificación y apoyo regional | D6: Suspendida por salida de asesores multieje. | E6: Sin avance
A7: 2 | B7: Identificar nuevos mercados potenciales | C7: Diversificación de mercados | D7: Posicionamiento en Corea del Sur, EAU, España, Francia. Asia +64%, África +238%. | E7: En progreso
A8: 3 | B8: Acciones de promoción enfocadas en diversificación | C8: Ferias y misiones | D8: 13 marcas en Aruba Fashion Week. 11 empresas al Dallas Market Center. MIPCOM Cannes. | E8: En progreso
A9: 4 | B9: Estrategia de internacionalización en África | C9: Ella Exporta a África | D9: Tercera visita oficial. Agendas B2B en países priorizados con 11 empresas. | E9: En progreso
A10: 5 | B10: Incremento de nuevas empresas exportando | C10: Acompañamiento a nuevas empresas | D10: 244 empresas nuevas en 2025 desde Industrias 4.0. MIGS y World Animation Summit. | E10: En progreso
A11: 6
A12: 7
A13: 8
A14: 9
A15: 10
A16: 11
A17: 12
A18: 13
A19: 14
A20: 15
A21: 16
A22: 17
... A26: 21
A28: INDICADORES DE ÉXITO / RESULTADOS
A29: # | B29: Indicador | C29: Meta 2026 | D29: Avance Acumulado Q | E29: Observaciones
A30: 1
A31: 2
A32: 3
A33: 4
A34: 5
A35: 6
A36: 7
A37: 8
A38: 9
A39: 10

Sheet LÍNEA ESTRATÉGICA 3
A1: LÍNEA ESTRATÉGICA 3
A2: Nombre de la línea: | B2: Preparar la oferta exportable de la gente para su proceso de internacionalización.
A4: ACCIONES Y ACTIVIDADES
A5: # | B5: Acción (Hoja de Ruta) | C5: Actividades Clave (Hoja de Ruta) | D5: Avance del Q (texto) | E5: Estado
A6: 1 | B6: Capacitación a empresarios en procesos de exportación | C6: Programas de formación | D6: Talleres de preparación para ferias y misiones internacionales. | E6: En progreso
A7: 2 | B7: Asistencia técnica en alistamiento exportador | C7: Acompañamiento MiPymes | D7: Cumplimiento de estándares internacionales en sectores priorizados. | E7: En progreso
A8: 3
A9: 4
A10: 5
A11: 6
A12: 7
A13: 8
A14: 9
A15: 10
A16: 11
A17: 12
A18: 13
A19: 14
... A26: 21
A28: INDICADORES DE ÉXITO / RESULTADOS
A29: # | B29: Indicador | C29: Meta 2026 | D29: Avance Acumulado Q | E29: Observaciones
A30: 1
A31: 2
A32: 3
A33: 4
A34: 5
A35: 6
A36: 7
A37: 8
A38: 9
A39: 10

Sheet CASOS DE ÉXITO
A1: CASOS DE ÉXITO
A2: Registre los casos de éxito más destacados del trimestre (máx. 400 caracteres por descripción).
A3: # | B3: Título del caso | C3: Descripción (máx 400 car.) | D3: Eje/Línea relacionada
A4: 1 | B4: Macrorrueda Bioexpo 2025 Pasto | C4: 84 exportadores, 34 compradores internacionales. Expectativas + ventas USD 6,4M. | D4: Línea 1
A5: 2 | B5: DYNAMO - Amazon España | C5: USD 6M con Amazon España. Estrategia ambiental GREENAMO. | D5: Línea 1
A6: 3 | B6: Estrategia África - Tercera visita oficial | C6: Agendas B2B con 11 empresas colombianas en países priorizados. | D6: Línea 2
A7: 4 | B7: Rueda Dotación Hotelera (9a edición) | C7: 69 exportadores, 22 compradores de 11 países. Canal HORECA. | D7: Línea 2
A8: 5 | B8: Plataforma Matchmaking | C8: Fase piloto con +700 empresas. Interacciones en tiempo real para 2026. | D8: Línea 1
A9: 6
A10: 7
A11: 8
A12: 9
A13: 10

Sheet METAS GENERALES
A1: RESUMEN DE METAS GENERALES
A3: # | B3: Indicador | C3: Meta Anual | D3: Avance Acumulado | E3: % Avance
A4: 1 | B4: Nuevas oportunidades exportaciones etapas 1 y 4 | C4: 16435 | D4: 20361 | E4: =IF(AND(C4<>"",C4<>0,D4<>""),D4/C4,"") -> 1.2388804
A5: 2 | B5: Nuevas empresas con oportunidades (1-4) | C5: 530 | D5: 1043 | E5: =IF(AND(C5<>"",C5<>0,D5<>""),D5/C5,"") -> 1.9679245
A6: 3 | B6: Monto de negocios (USD miles) | C6: 4286 | D6: 3195959 | E6: =IF(AND(C6<>"",C6<>0,D6<>""),D6/C6,"") -> 745.67406
A7: 4 | B7: Compradores con negocios | C7: 5550 | D7: 6346 | E7: =IF(AND(C7<>"",C7<>0,D7<>""),D7/C7,"") -> 1.1434234
A8: 5 | B8: Compradores nuevos con negocios | C8: 2293 | D8: 3156 | E8: =IF(AND(C8<>"",C8<>0,D8<>""),D8/C8,"") -> 1.3763628
A9: 6 | B9: Empresas exterior con servicios exportación | C9: 6318 | D9: 5961 | E9: =IF(AND(C9<>"",C9<>0,D9<>""),D9/C9,"") -> 0.94349478
A10: 7 | B10: Empresas con negocios | C10: 3330 | D10: 3392 | E10: =IF(AND(C10<>"",C10<>0,D10<>""),D10/C10,"") -> 1.0186186
A11: 8 | B11: Empresas con negocios (Mipymes) | C11: 2000 | D11: 2753 | E11: =IF(AND(C11<>"",C11<>0,D11<>""),D11/C11,"") -> 1.3765
A12: 9 | B12: Empresas colombianas con servicios exportación | C12: 5760 | D12: 791 | E12: =IF(AND(C12<>"",C12<>0,D12<>""),D12/C12,"") -> 0.13732639
A13: 10 | B13: Actividades de promoción comercial | C13: 40 | D13: 50 | E13: =IF(AND(C13<>"",C13<>0,D13<>""),D13/C13,"") -> 1.25
A14: 11 | E14: =IF(AND(C14<>"",C14<>0,D14<>""),D14/C14,"")
A15: 12 | E15: =IF(AND(C15<>"",C15<>0,D15<>""),D15/C15,"")
A16: 13 | E16: =IF(AND(C16<>"",C16<>0,D16<>""),D16/C16,"")
A17: 14 | E17: =IF(AND(C17<>"",C17<>0,D17<>""),D17/C17,"")
A18: 15 | E18: =IF(AND(C18<>"",C18<>0,D18<>""),D18/C18,"")

Sheet MONITOREO
A1: PANEL DE MONITOREO — COMPLETITUD
A2: Este panel se calcula automáticamente. No editar.
A4: Sección | B4: Ítems con datos | C4: Total esperado | D4: % Completitud
A5: DOFA — Estados | B5: =COUNTA(DOFA!C6:C45)-COUNTBLANK(DOFA!C6:C45) -> 22 | C5: =COUNTA(DOFA!B6:B45)-COUNTBLANK(DOFA!B6:B45) -> 22 | D5: =IF(C5>0,B5/C5,0) -> 1
A6: Tendencias — Estados | B6: =COUNTA(TENDENCIAS!C5:C11)-COUNTBLANK(TENDENCIAS!C5:C11) -> 3 | C6: =COUNTA(TENDENCIAS!B5:B11)-COUNTBLANK(TENDENCIAS!B5:B11) -> 3 | D6: =IF(C6>0,B6/C6,0) -> 1
A7: Línea 1 — Avances Acciones | B7: =COUNTA('LÍNEA ESTRATÉGICA 1'!D6:D26)-COUNTBLANK('LÍNEA ESTRATÉGICA 1'!D6:D26) -> -5 | C7: =COUNTA('LÍNEA ESTRATÉGICA 1'!B6:B26)-COUNTBLANK('LÍNEA ESTRATÉGICA 1'!B6:B26) -> -5 | D7: =IF(C7>0,B7/C7,0) -> 0
A8: Línea 1 — Estados Acciones | B8: =COUNTA('LÍNEA ESTRATÉGICA 1'!E6:E26)-COUNTBLANK('LÍNEA ESTRATÉGICA 1'!E6:E26) -> -5 | C8: =COUNTA('LÍNEA ESTRATÉGICA 1'!B6:B26)-COUNTBLANK('LÍNEA ESTRATÉGICA 1'!B6:B26) -> -5 | D8: =IF(C8>0,B8/C8,0) -> 0
A9: Línea 1 — Avance Indicadores | B9: =COUNTA('LÍNEA ESTRATÉGICA 1'!D30:D39)-COUNTBLANK('LÍNEA ESTRATÉGICA 1'!D30:D39) -> 6 | C9: =COUNTA('LÍNEA ESTRATÉGICA 1'!B30:B39)-COUNTBLANK('LÍNEA ESTRATÉGICA 1'!B30:B39) -> 6 | D9: =IF(C9>0,B9/C9,0) -> 1
A10: Línea 2 — Avances Acciones | B10: =COUNTA('LÍNEA ESTRATÉGICA 2'!D6:D26)-COUNTBLANK('LÍNEA ESTRATÉGICA 2'!D6:D26) -> -11 | C10: =COUNTA('LÍNEA ESTRATÉGICA 2'!B6:B26)-COUNTBLANK('LÍNEA ESTRATÉGICA 2'!B6:B26) -> -11 | D10: =IF(C10>0,B10/C10,0) -> 0
A11: Línea 2 — Estados Acciones | B11: =COUNTA('LÍNEA ESTRATÉGICA 2'!E6:E26)-COUNTBLANK('LÍNEA ESTRATÉGICA 2'!E6:E26) -> -11 | C11: =COUNTA('LÍNEA ESTRATÉGICA 2'!B6:B26)-COUNTBLANK('LÍNEA ESTRATÉGICA 2'!B6:B26) -> -11 | D11: =IF(C11>0,B11/C11,0) -> 0
A12: Línea 2 — Avance Indicadores | B12: =COUNTA('LÍNEA ESTRATÉGICA 2'!D30:D39)-COUNTBLANK('LÍNEA ESTRATÉGICA 2'!D30:D39) -> -10 | C12: =COUNTA('LÍNEA ESTRATÉGICA 2'!B30:B39)-COUNTBLANK('LÍNEA ESTRATÉGICA 2'!B30:B39) -> -10 | D12: =IF(C12>0,B12/C12,0) -> 0
A13: Línea 3 — Avances Acciones | B13: =COUNTA('LÍNEA ESTRATÉGICA 3'!D6:D26)-COUNTBLANK('LÍNEA ESTRATÉGICA 3'!D6:D26) -> -17 | C13: =COUNTA('LÍNEA ESTRATÉGICA 3'!B6:B26)-COUNTBLANK('LÍNEA ESTRATÉGICA 3'!B6:B26) -> -17 | D13: =IF(C13>0,B13/C13,0) -> 0
A14: Línea 3 — Estados Acciones | B14: =COUNTA('LÍNEA ESTRATÉGICA 3'!E6:E26)-COUNTBLANK('LÍNEA ESTRATÉGICA 3'!E6:E26) -> -17 | C14: =COUNTA('LÍNEA ESTRATÉGICA 3'!B6:B26)-COUNTBLANK('LÍNEA ESTRATÉGICA 3'!B6:B26) -> -17 | D14: =IF(C14>0,B14/C14,0) -> 0
A15: Línea 3 — Avance Indicadores | B15: =COUNTA('LÍNEA ESTRATÉGICA 3'!D30:D39)-COUNTBLANK('LÍNEA ESTRATÉGICA 3'!D30:D39) -> -10 | C15: =COUNTA('LÍNEA ESTRATÉGICA 3'!B30:B39)-COUNTBLANK('LÍNEA ESTRATÉGICA 3'!B30:B39) -> -10 | D15: =IF(C15>0,B15/C15,0) -> 0
A16: Casos de Éxito | B16: =COUNTA('CASOS DE ÉXITO'!B4:B13)-COUNTBLANK('CASOS DE ÉXITO'!B4:B13) -> 0 | C16: =MAX(1,COUNTA('CASOS DE ÉXITO'!B4:B13)-COUNTBLANK('CASOS DE ÉXITO'!B4:B13)) -> 1 | D16: =IF(C16>0,B16/C16,0) -> 0
A17: Metas Generales — Avance | B17: =COUNTA('METAS GENERALES'!D4:D18)-COUNTBLANK('METAS GENERALES'!D4:D18) -> 5 | C17: =COUNTA('METAS GENERALES'!C4:C18)-COUNTBLANK('METAS GENERALES'!C4:C18) -> 5 | D17: =IF(C17>0,B17/C17,0) -> 1
A19: COMPLETITUD GLOBAL PROMEDIO | D19: =AVERAGE(D5:D17) -> 0.30769231
